ERROR:root:The source side of a relation of type rdfs:subClassOf and id 89 is not connected or even close to any shape, verify it!
Traceback (most recent call last):
  File "D:\Projects\diagram2code\modules\utils.py", line 152, in fix_source_target
    relation["uri"] + " is not connected or even close to any shape, verify it!")
KeyError: 'prefix'

During handling of the above exception, another exception occurred:

Traceback (most recent call last):
  File "converter.py", line 79, in <module>
    transform_ontology(root, args.output_path)
  File "converter.py", line 15, in transform_ontology
    relations = fix_source_target(relations, [concepts, attribute_blocks, individuals, anonymous_concepts, rhombuses])
  File "D:\Projects\diagram2code\modules\utils.py", line 155, in fix_source_target
    " and id " + id + " is not connected or even close to any shape, "
ValueError: The source side of a relation of type rdfs:subClassOf and id 89 is not connected or even close to any shape, verify it!
ERROR:root:The source side of a relation of type rdfs:subClassOf and id 89 is not connected or even close to any shape, verify it!
Traceback (most recent call last):
  File "D:\Projects\diagram2code\modules\utils.py", line 152, in fix_source_target
    relation["uri"] + " is not connected or even close to any shape, verify it!")
KeyError: 'prefix'

During handling of the above exception, another exception occurred:

Traceback (most recent call last):
  File "converter.py", line 79, in <module>
    transform_ontology(root, args.output_path)
  File "converter.py", line 15, in transform_ontology
    relations = fix_source_target(relations, [concepts, attribute_blocks, individuals, anonymous_concepts, rhombuses])
  File "D:\Projects\diagram2code\modules\utils.py", line 155, in fix_source_target
    " and id " + id + " is not connected or even close to any shape, "
ValueError: The source side of a relation of type rdfs:subClassOf and id 89 is not connected or even close to any shape, verify it!
ERROR:root:'54'
Traceback (most recent call last):
  File "converter.py", line 79, in <module>
    transform_ontology(root, args.output_path)
  File "converter.py", line 19, in transform_ontology
    associations, relations = concept_relation_association(associations, relations)
  File "D:\Projects\diagram2code\modules\associations.py", line 58, in concept_relation_association
    associations[s_concept_id]["relations"][relation_id]["target"] = t_concept_id
KeyError: '54'
ERROR:root:'54'
Traceback (most recent call last):
  File "converter.py", line 79, in <module>
    transform_ontology(root, args.output_path)
  File "converter.py", line 19, in transform_ontology
    associations, relations = concept_relation_association(associations, relations)
  File "D:\Projects\diagram2code\modules\associations.py", line 58, in concept_relation_association
    associations[s_concept_id]["relations"][relation_id]["target"] = t_concept_id
KeyError: '54'
ERROR:root:'54'
Traceback (most recent call last):
  File "converter.py", line 79, in <module>
    transform_ontology(root, args.output_path)
  File "converter.py", line 19, in transform_ontology
    associations, relations = concept_relation_association(associations, relations)
  File "D:\Projects\diagram2code\modules\associations.py", line 59, in concept_relation_association
    associations[s_concept_id]["relations"][relation_id]["target"] = t_concept_id
KeyError: '54'
ERROR:root:'3'
Traceback (most recent call last):
  File "converter.py", line 79, in <module>
    transform_ontology(root, args.output_path)
  File "converter.py", line 20, in transform_ontology
    individuals = individual_type_identification(individuals, associations, relations)
  File "D:\Projects\diagram2code\modules\associations.py", line 70, in individual_type_identification
    individual = individuals[source_id]
KeyError: '3'
ERROR:root:'x'
Traceback (most recent call last):
  File "converter.py", line 79, in <module>
    transform_ontology(root, args.output_path)
  File "converter.py", line 11, in transform_ontology
    all_elements = finder.find_elements()
  File "D:\Projects\diagram2code\modules\finding.py", line 540, in find_elements
    concepts, attribute_blocks = self.find_concepts_and_attributes()
  File "D:\Projects\diagram2code\modules\finding.py", line 448, in find_concepts_and_attributes
    p1_support, p2_support, p3_support, p4_support = get_corners_rect_child(child2)
  File "D:\Projects\diagram2code\modules\geometry.py", line 16, in get_corners_rect_child
    x, y = float(geometry.attrib["x"]), float(geometry.attrib["y"])
KeyError: 'x'
ERROR:root:'x'
Traceback (most recent call last):
  File "converter.py", line 79, in <module>
    transform_ontology(root, args.output_path)
  File "converter.py", line 11, in transform_ontology
    all_elements = finder.find_elements()
  File "D:\Projects\diagram2code\modules\finding.py", line 541, in find_elements
    concepts, attribute_blocks = self.find_concepts_and_attributes()
  File "D:\Projects\diagram2code\modules\finding.py", line 449, in find_concepts_and_attributes
    p1_support, p2_support, p3_support, p4_support = get_corners_rect_child(child2)
  File "D:\Projects\diagram2code\modules\geometry.py", line 16, in get_corners_rect_child
    x, y = float(geometry.attrib["x"]), float(geometry.attrib["y"])
KeyError: 'x'
ERROR:root:The following prefixes were not found in the namespace declaration: geo, s4blsg
Traceback (most recent call last):
  File "converter.py", line 79, in <module>
    transform_ontology(root, args.output_path)
  File "converter.py", line 22, in transform_ontology
    file, onto_prefix, onto_uri = get_ttl_template(filename, namespaces, prefixes_identified)
  File "D:\Projects\diagram2code\modules\writer.py", line 21, in get_ttl_template
    raise ValueError("The following prefixes were not found in the namespace declaration: " + prefixes_string)
ValueError: The following prefixes were not found in the namespace declaration: geo, s4blsg
ERROR:root:must be str, not NoneType
Traceback (most recent call last):
  File "converter.py", line 79, in <module>
    transform_ontology(root, args.output_path)
  File "converter.py", line 26, in transform_ontology
    file = write_concepts(file, concepts, anonymous_concepts, associations)
  File "D:\Projects\diagram2code\modules\writer.py", line 242, in write_concepts
    file.write("\t\t  owl:onDataRange xsd:" + attribute["datatype"] + " ]")
TypeError: must be str, not NoneType
ERROR:root:'type'
Traceback (most recent call last):
  File "converter.py", line 79, in <module>
    transform_ontology(root, args.output_path)
  File "converter.py", line 11, in transform_ontology
    all_elements = finder.find_elements()
  File "D:\Projects\diagram2code\modules\finding.py", line 544, in find_elements
    ellipses = self.find_ellipses()
  File "D:\Projects\diagram2code\modules\finding.py", line 285, in find_ellipses
    if relation["type"] == "ellipse_connection":
KeyError: 'type'
